Workbook

Sheet Membership Payment Plans
O14: *If paid off in 3 months we remove the interest
O15: What about 5 year?

Sheet InHouse Purchases
A1: PURCHASE | C1: EXPENSE ACCOUNT
A4: Plants Dept - Water/Drinks | C4: Member Appreciation
A5: Chill Room-Water/Snacks | C5: Staff Appreciation
A6: Grocery Cart Returns | C6: Maint - Equip
A7: Parking | C7: 8424000 · Admn -Travel Transportation Exp
A8: Snap Initiative | C8: Admin Miscellaneous expense
A21: Building Block | C21: S:\Finance & Payroll Forms\Finance Work Files\Building Blocks

Sheet Random Sales
A1: RANDOM SALE | B1: ACCOUNT TO CREDIT
A2: Books | B2: Magazines
A3: Candles/Incense | B3: Mercantile
A4: Coop Scoop | B4: Look up code to left (usually CDTA Bus Passes)
A5: CDTA Bus Passes | B5: Promotional Sales

Sheet SMS Look Up
A1: Member Shares | B1: Journal>Totalizers>Totalizer> Change Date> 3420

Sheet SubDept Single
A1: 27 | B1: Store coupons | G1: -684.02
A2: 28 | B2: Store Supplies | F2: 61 | G2: 6.1
A3: 38 | B3: NYS-Alb Cty Bags | F3: 69 | G3: 3.45
A4: 110 | B4: Grocery Non-Tax | F4: 2885 | G4: 12743.11
A5: 120 | B5: Refrigerated | F5: 1903 | G5: 9256.64
A6: 130 | B6: Frozen Foods | F6: 418 | G6: 2723.74
A7: 140 | B7: Bulk | F7: 1193 | G7: 8090.18
A8: 142 | B8: Bulk Teas/Spices | F8: 178 | G8: 859.01
A9: 150 | B9: Bread and Bakery | F9: 383 | G9: 2216.58
A10: 160 | B10: Beer/Alcohol | F10: 81 | G10: 799.54
A11: 180 | B11: Pet Supplies | F11: 44 | G11: 253.56
A12: 190 | B12: General Merchandise | F12: 126 | G12: 882.84
A13: 210 | B13: In House Deli | F13: 1110 | G13: 9533.9
... A28: 1300 | B28: Promotional | F28: 25 | G28: 158.84

Sheet SubDept Coupon (Local Discount)
A1: 110 | B1: Grocery Non-Tax | F1: 16 | G1: 6.42
A2: 120 | B2: Refrigerated | F2: 38 | G2: 20.2
A3: 130 | B3: Frozen Foods | F3: 4 | G3: 3.11
A4: 140 | B4: Bulk | F4: 2 | G4: 0.85
A5: 142 | B5: Bulk Teas/Spices | F5: 135
A6: 150 | B6: Bread and Bakery | F6: 34 | G6: 13.62
A7: 160 | B7: Beer/Alcohol | F7: 13 | G7: 6.65
A8: 210 | B8: In House Deli | F8: 16
A9: 220 | B9: In House Bakery | F9: 2 | G9: 1.78
A10: 310 | B10: Cheese | F10: 4 | G10: 2.23
A11: 320 | B11: Meat | F11: 12
A12: 330 | B12: Specialty Foods | F12: 4 | G12: 5.5
A13: 410 | B13: Produce | F13: 5 | G13: 1.45
A14: 510 | B14: BodyCare (Tax) | F14: 1 | G14: 0.17
A15: 520 | B15: Supplements | F15: 1 | G15: 1.35

Sheet Maria College 1 Sales Data

Sheet Maria College 2 Sales Data

Sheet SubDept Sales Report
A1: Sub-Dept. Single Total Report | I1: Store Coupons: | J1: =G10 -> -684.02 | L1: Milk Bottles Returns | M1: =28+8+18+24 -> 78 | O1: Refunded Discounts | P1: 13.31
I2: Owner Apprec. (5%) Total: | J2: =D54*-1 -> -63.33 | L2: Store Coupons | M2: =J1+M1 -> -606.02 | O2: Bunnies | P2: 0
I3: Sales Total: | J3: =G54+J1+J2 -> 87114.32 | O3: Pass Through Donations | P3: 0.75
A4: Sub-Dept. Number | B4: Sub-Dept. | C4: Sales Total | D4: Coupon Total | E4: Maria 1 Sales | F4: Maria 2 Sales | G4: Sub-Dept. Single Total | O4: Total | P4: =SUM(P1:P3) -> 14.06
A5: 22 | B5: Coop Scoop Ad payment | C5: =IFERROR(INDEX('SubDept Single'!G$1:G$100,MATCH('SubDept Sales Report'!A5,'SubDept Single'!A$1:A$100,0)),0) -> 0 | D5: =IFERROR(INDEX('SubDept Coupon (Local Discount)'!G$1:G$100,MATCH('SubDept Sales Report'!A5,'SubDept Coupon (Local Discount)'!A$1:A$100,0)),0) -> 0 | E5: =IFERROR(SUMIF('Maria College 1 Sales Data'!D$11:D$2500,A5,'Maria College 1 Sales Data'!G$11:G$2500),0) -> 0 | F5: =IFERROR(SUMIF('Maria College 2 Sales Data'!D$11:D$2500,A5,'Maria College 2 Sales Data'!G$11:G$2500),0) -> 0 | G5: =(C5+D5)-E5-F5 -> 0
A6: 23 | B6: Refunded Discounts | C6: =IFERROR(INDEX('SubDept Single'!G$1:G$100,MATCH('SubDept Sales Report'!A6,'SubDept Single'!A$1:A$100,0)),0) -> 0 | D6: =IFERROR(INDEX('SubDept Coupon (Local Discount)'!G$1:G$100,MATCH('SubDept Sales Report'!A6,'SubDept Coupon (Local Discount)'!A$1:A$100,0)),0) -> 0 | E6: =SUMIF('Maria College 1 Sales Data'!D$11:D$2500,A6,'Maria College 1 Sales Data'!G$11:G$2500) -> 0 | F6: =IFERROR(SUMIF('Maria College 2 Sales Data'!D$11:D$2500,A6,'Maria College 2 Sales Data'!G$11:G$2500),0) -> 0 | G6: =(C6+D6)-E6-F6 -> 0
A7: 24 | B7: bottle deposits | C7: =IFERROR(INDEX('SubDept Single'!G$1:G$100,MATCH('SubDept Sales Report'!A7,'SubDept Single'!A$1:A$100,0)),0) -> 0 | D7: =IFERROR(INDEX('SubDept Coupon (Local Discount)'!G$1:G$100,MATCH('SubDept Sales Report'!A7,'SubDept Coupon (Local Discount)'!A$1:A$100,0)),0) -> 0 | E7: =SUMIF('Maria College 1 Sales Data'!D$11:D$2500,A7,'Maria College 1 Sales Data'!G$11:G$2500) -> 0 | F7: =IFERROR(SUMIF('Maria College 2 Sales Data'!D$11:D$2500,A7,'Maria College 2 Sales Data'!G$11:G$2500),0) -> 0 | G7: =(C7+D7)-E7-F7 -> 0
A8: 25 | B8: gift certificates | C8: =IFERROR(INDEX('SubDept Single'!G$1:G$100,MATCH('SubDept Sales Report'!A8,'SubDept Single'!A$1:A$100,0)),0) -> 0 | D8: =IFERROR(INDEX('SubDept Coupon (Local Discount)'!G$1:G$100,MATCH('SubDept Sales Report'!A8,'SubDept Coupon (Local Discount)'!A$1:A$100,0)),0) -> 0 | E8: =SUMIF('Maria College 1 Sales Data'!D$11:D$2500,A8,'Maria College 1 Sales Data'!G$11:G$2500) -> 0 | F8: =IFERROR(SUMIF('Maria College 2 Sales Data'!D$11:D$2500,A8,'Maria College 2 Sales Data'!G$11:G$2500),0) -> 0 | G8: =(C8+D8)-E8-F8 -> 0
A9: 26 | B9: SHARE PAYMENT | C9: =IFERROR(INDEX('SubDept Single'!G$1:G$100,MATCH('SubDept Sales Report'!A9,'SubDept Single'!A$1:A$100,0)),0) -> 0 | D9: =IFERROR(INDEX('SubDept Coupon (Local Discount)'!G$1:G$100,MATCH('SubDept Sales Report'!A9,'SubDept Coupon (Local Discount)'!A$1:A$100,0)),0) -> 0 | E9: =SUMIF('Maria College 1 Sales Data'!D$11:D$2500,A9,'Maria College 1 Sales Data'!G$11:G$2500) -> 0 | F9: =IFERROR(SUMIF('Maria College 2 Sales Data'!D$11:D$2500,A9,'Maria College 2 Sales Data'!G$11:G$2500),0) -> 0 | G9: =(C9+D9)-E9-F9 -> 0
A10: 27 | B10: Store coupons | C10: =IFERROR(INDEX('SubDept Single'!G$1:G$100,MATCH('SubDept Sales Report'!A10,'SubDept Single'!A$1:A$100,0)),0) -> -684.02 | D10: =IFERROR(INDEX('SubDept Coupon (Local Discount)'!G$1:G$100,MATCH('SubDept Sales Report'!A10,'SubDept Coupon (Local Discount)'!A$1:A$100,0)),0) -> 0 | E10: 0 | F10: 0 | G10: =C10+D10 -> -684.02
A11: 28 | B11: Store Supplies | C11: =IFERROR(INDEX('SubDept Single'!G$1:G$100,MATCH('SubDept Sales Report'!A11,'SubDept Single'!A$1:A$100,0)),0) -> 6.1 | D11: =IFERROR(INDEX('SubDept Coupon (Local Discount)'!G$1:G$100,MATCH('SubDept Sales Report'!A11,'SubDept Coupon (Local Discount)'!A$1:A$100,0)),0) -> 0 | E11: =SUMIF('Maria College 1 Sales Data'!D$11:D$2500,A11,'Maria College 1 Sales Data'!G$11:G$2500) -> 0 | F11: =IFERROR(SUMIF('Maria College 2 Sales Data'!D$11:D$2500,A11,'Maria College 2 Sales Data'!G$11:G$2500),0) -> 0 | G11: =(C11+D11)-E11-F11 -> 6.1
A12: 29 | B12: Building Blocks | C12: =IFERROR(INDEX('SubDept Single'!G$1:G$100,MATCH('SubDept Sales Report'!A12,'SubDept Single'!A$1:A$100,0)),0) -> 0 | D12: =IFERROR(INDEX('SubDept Coupon (Local Discount)'!G$1:G$100,MATCH('SubDept Sales Report'!A12,'SubDept Coupon (Local Discount)'!A$1:A$100,0)),0) -> 0 | E12: =SUMIF('Maria College 1 Sales Data'!D$11:D$2500,A12,'Maria College 1 Sales Data'!G$11:G$2500) -> 0 | F12: =IFERROR(SUMIF('Maria College 2 Sales Data'!D$11:D$2500,A12,'Maria College 2 Sales Data'!G$11:G$2500),0) -> 0 | G12: =(C12+D12)-E12-F12 -> 0
A13: 30 | B13: Groupon | C13: =IFERROR(INDEX('SubDept Single'!G$1:G$100,MATCH('SubDept Sales Report'!A13,'SubDept Single'!A$1:A$100,0)),0) -> 0 | D13: =IFERROR(INDEX('SubDept Coupon (Local Discount)'!G$1:G$100,MATCH('SubDept Sales Report'!A13,'SubDept Coupon (Local Discount)'!A$1:A$100,0)),0) -> 0 | E13: =SUMIF('Maria College 1 Sales Data'!D$11:D$2500,A13,'Maria College 1 Sales Data'!G$11:G$2500) -> 0 | F13: =IFERROR(SUMIF('Maria College 2 Sales Data'!D$11:D$2500,A13,'Maria College 2 Sales Data'!G$11:G$2500),0) -> 0 | G13: =(C13+D13)-E13-F13 -> 0
A14: 31 | B14: Crowd Savings | C14: =IFERROR(INDEX('SubDept Single'!G$1:G$100,MATCH('SubDept Sales Report'!A14,'SubDept Single'!A$1:A$100,0)),0) -> 0 | D14: =IFERROR(INDEX('SubDept Coupon (Local Discount)'!G$1:G$100,MATCH('SubDept Sales Report'!A14,'SubDept Coupon (Local Discount)'!A$1:A$100,0)),0) -> 0 | E14: =SUMIF('Maria College 1 Sales Data'!D$11:D$2500,A14,'Maria College 1 Sales Data'!G$11:G$2500) -> 0 | F14: =IFERROR(SUMIF('Maria College 2 Sales Data'!D$11:D$2500,A14,'Maria College 2 Sales Data'!G$11:G$2500),0) -> 0 | G14: =(C14+D14)-E14-F14 -> 0
A15: 32 | B15: PASS THROUGH DONATIONS | C15: =IFERROR(INDEX('SubDept Single'!G$1:G$100,MATCH('SubDept Sales Report'!A15,'SubDept Single'!A$1:A$100,0)),0) -> 0 | D15: =IFERROR(INDEX('SubDept Coupon (Local Discount)'!G$1:G$100,MATCH('SubDept Sales Report'!A15,'SubDept Coupon (Local Discount)'!A$1:A$100,0)),0) -> 0 | E15: =SUMIF('Maria College 1 Sales Data'!D$11:D$2500,A15,'Maria College 1 Sales Data'!G$11:G$2500) -> 0 | F15: =IFERROR(SUMIF('Maria College 2 Sales Data'!D$11:D$2500,A15,'Maria College 2 Sales Data'!G$11:G$2500),0) -> 0 | G15: =(C15+D15)-E15-F15 -> 0
A16: 33 | B16: Bag Credits | C16: =IFERROR(INDEX('SubDept Single'!G$1:G$100,MATCH('SubDept Sales Report'!A16,'SubDept Single'!A$1:A$100,0)),0) -> 0 | D16: =IFERROR(INDEX('SubDept Coupon (Local Discount)'!G$1:G$100,MATCH('SubDept Sales Report'!A16,'SubDept Coupon (Local Discount)'!A$1:A$100,0)),0) -> 0 | E16: =SUMIF('Maria College 1 Sales Data'!D$11:D$2500,A16,'Maria College 1 Sales Data'!G$11:G$2500) -> 0 | F16: =IFERROR(SUMIF('Maria College 2 Sales Data'!D$11:D$2500,A16,'Maria College 2 Sales Data'!G$11:G$2500),0) -> 0 | G16: =(C16+D16)-E16-F16 -> 0
A17: 34 | B17: PAID-INS | C17: =IFERROR(INDEX('SubDept Single'!G$1:G$100,MATCH('SubDept Sales Report'!A17,'SubDept Single'!A$1:A$100,0)),0) -> 0 | D17: =IFERROR(INDEX('SubDept Coupon (Local Discount)'!G$1:G$100,MATCH('SubDept Sales Report'!A17,'SubDept Coupon (Local Discount)'!A$1:A$100,0)),0) -> 0 | E17: =SUMIF('Maria College 1 Sales Data'!D$11:D$2500,A17,'Maria College 1 Sales Data'!G$11:G$2500) -> 0 | F17: =IFERROR(SUMIF('Maria College 2 Sales Data'!D$11:D$2500,A17,'Maria College 2 Sales Data'!G$11:G$2500),0) -> 0 | G17: =(C17+D17)-E17-F17 -> 0
A18: 35 | B18: Owner Appreciation 5% | C18: =IFERROR(INDEX('SubDept Single'!G$1:G$100,MATCH('SubDept Sales Report'!A18,'SubDept Single'!A$1:A$100,0)),0) -> 0 | D18: =IFERROR(INDEX('SubDept Coupon (Local Discount)'!G$1:G$100,MATCH('SubDept Sales Report'!A18,'SubDept Coupon (Local Discount)'!A$1:A$100,0)),0) -> 0 | E18: =SUMIF('Maria College 1 Sales Data'!D$11:D$2500,A18,'Maria College 1 Sales Data'!G$11:G$2500) -> 0 | F18: =IFERROR(SUMIF('Maria College 2 Sales Data'!D$11:D$2500,A18,'Maria College 2 Sales Data'!G$11:G$2500),0) -> 0 | G18: =(C18+D18)-E18-F18 -> 0
A19: 37 | B19: TESTStaff Appreciation | C19: =IFERROR(INDEX('SubDept Single'!G$1:G$100,MATCH('SubDept Sales Report'!A19,'SubDept Single'!A$1:A$100,0)),0) -> 0 | D19: =IFERROR(INDEX('SubDept Coupon (Local Discount)'!G$1:G$100,MATCH('SubDept Sales Report'!A19,'SubDept Coupon (Local Discount)'!A$1:A$100,0)),0) -> 0 | E19: =SUMIF('Maria College 1 Sales Data'!D$11:D$2500,A19,'Maria College 1 Sales Data'!G$11:G$2500) -> 0 | F19: =IFERROR(SUMIF('Maria College 2 Sales Data'!D$11:D$2500,A19,'Maria College 2 Sales Data'!G$11:G$2500),0) -> 0 | G19: =(C19+D19)-E19-F19 -> 0
A20: 38 | B20: NYS-Alb Cty Bags | C20: =IFERROR(INDEX('SubDept Single'!G$1:G$100,MATCH('SubDept Sales Report'!A20,'SubDept Single'!A$1:A$100,0)),0) -> 3.45 | D20: =IFERROR(INDEX('SubDept Coupon (Local Discount)'!G$1:G$100,MATCH('SubDept Sales Report'!A20,'SubDept Coupon (Local Discount)'!A$1:A$100,0)),0) -> 0 | E20: =SUMIF('Maria College 1 Sales Data'!D$11:D$2500,A20,'Maria College 1 Sales Data'!G$11:G$2500) -> 0 | F20: =IFERROR(SUMIF('Maria College 2 Sales Data'!D$11:D$2500,A20,'Maria College 2 Sales Data'!G$11:G$2500),0) -> 0 | G20: =(C20+D20)-E20-F20 -> 3.45
A21: 50 | B21: ENVIROTOKENS | C21: =IFERROR(INDEX('SubDept Single'!G$1:G$100,MATCH('SubDept Sales Report'!A21,'SubDept Single'!A$1:A$100,0)),0) -> 0 | D21: =IFERROR(INDEX('SubDept Coupon (Local Discount)'!G$1:G$100,MATCH('SubDept Sales Report'!A21,'SubDept Coupon (Local Discount)'!A$1:A$100,0)),0) -> 0 | E21: =SUMIF('Maria College 1 Sales Data'!D$11:D$2500,A21,'Maria College 1 Sales Data'!G$11:G$2500) -> 0 | F21: =IFERROR(SUMIF('Maria College 2 Sales Data'!D$11:D$2500,A21,'Maria College 2 Sales Data'!G$11:G$2500),0) -> 0 | G21: =(C21+D21)-E21-F21 -> 0
A22: 110 | B22: Grocery Non-Tax | C22: =IFERROR(INDEX('SubDept Single'!G$1:G$100,MATCH('SubDept Sales Report'!A22,'SubDept Single'!A$1:A$100,0)),0) -> 12743.11 | D22: =IFERROR(INDEX('SubDept Coupon (Local Discount)'!G$1:G$100,MATCH('SubDept Sales Report'!A22,'SubDept Coupon (Local Discount)'!A$1:A$100,0)),0) -> 6.42 | E22: =SUMIF('Maria College 1 Sales Data'!D$11:D$2500,A22,'Maria College 1 Sales Data'!G$11:G$2500) -> 0 | F22: =IFERROR(SUMIF('Maria College 2 Sales Data'!D$11:D$2500,A22,'Maria College 2 Sales Data'!G$11:G$2500),0) -> 0 | G22: =(C22+D22)-E22-F22 -> 12749.53
... A33: 220 | B33: In House Bakery | C33: =IFERROR(INDEX('SubDept Single'!G$1:G$100,MATCH('SubDept Sales Report'!A33,'SubDept Single'!A$1:A$100,0)),0) -> 2394.98 | D33: =IFERROR(INDEX('SubDept Coupon (Local Discount)'!G$1:G$100,MATCH('SubDept Sales Report'!A33,'SubDept Coupon (Local Discount)'!A$1:A$100,0)),0) -> 1.78 | E33: =SUMIF('Maria College 1 Sales Data'!D$11:D$2500,A33,'Maria College 1 Sales Data'!G$11:G$2500) -> 0 | F33: =IFERROR(SUMIF('Maria College 2 Sales Data'!D$11:D$2500,A33,'Maria College 2 Sales Data'!G$11:G$2500),0) -> 0 | G33: =(C33+D33)-E33-F33 -> 2396.76
A34: 230 | B34: Catering | C34: =IFERROR(INDEX('SubDept Single'!G$1:G$100,MATCH('SubDept Sales Report'!A34,'SubDept Single'!A$1:A$100,0)),0) -> 455.73 | D34: =IFERROR(INDEX('SubDept Coupon (Local Discount)'!G$1:G$100,MATCH('SubDept Sales Report'!A34,'SubDept Coupon (Local Discount)'!A$1:A$100,0)),0) -> 0 | E34: 0 | F34: 0 | G34: =C34+D34 -> 455.73
A35: 235 | B35: Sushi | C35: =IFERROR(INDEX('SubDept Single'!G$1:G$100,MATCH('SubDept Sales Report'!A35,'SubDept Single'!A$1:A$100,0)),0) -> 953.65 | D35: =IFERROR(INDEX('SubDept Coupon (Local Discount)'!G$1:G$100,MATCH('SubDept Sales Report'!A35,'SubDept Coupon (Local Discount)'!A$1:A$100,0)),0) -> 0 | E35: =SUMIF('Maria College 1 Sales Data'!D$11:D$2500,A35,'Maria College 1 Sales Data'!G$11:G$2500) -> 0 | F35: =IFERROR(SUMIF('Maria College 2 Sales Data'!D$11:D$2500,A35,'Maria College 2 Sales Data'!G$11:G$2500),0) -> 0 | G35: =(C35+D35)-E35-F35 -> 953.65
A36: 240 | B36: Java & Juice | C36: =IFERROR(INDEX('SubDept Single'!G$1:G$100,MATCH('SubDept Sales Report'!A36,'SubDept Single'!A$1:A$100,0)),0) -> 660.65 | D36: =IFERROR(INDEX('SubDept Coupon (Local Discount)'!G$1:G$100,MATCH('SubDept Sales Report'!A36,'SubDept Coupon (Local Discount)'!A$1:A$100,0)),0) -> 0 | E36: =SUMIF('Maria College 1 Sales Data'!D$11:D$2500,A36,'Maria College 1 Sales Data'!G$11:G$2500) -> 0 | F36: =IFERROR(SUMIF('Maria College 2 Sales Data'!D$11:D$2500,A36,'Maria College 2 Sales Data'!G$11:G$2500),0) -> 0 | G36: =(C36+D36)-E36-F36 -> 660.65
A37: 250 | B37: ESP - Co-op Cafe | C37: =IFERROR(INDEX('SubDept Single'!G$1:G$100,MATCH('SubDept Sales Report'!A37,'SubDept Single'!A$1:A$100,0)),0) -> 1001.45 | D37: =IFERROR(INDEX('SubDept Coupon (Local Discount)'!G$1:G$100,MATCH('SubDept Sales Report'!A37,'SubDept Coupon (Local Discount)'!A$1:A$100,0)),0) -> 0 | E37: =SUMIF('Maria College 1 Sales Data'!D$11:D$2500,A37,'Maria College 1 Sales Data'!G$11:G$2500) -> 0 | F37: =IFERROR(SUMIF('Maria College 2 Sales Data'!D$11:D$2500,A37,'Maria College 2 Sales Data'!G$11:G$2500),0) -> 0 | G37: =(C37+D37)-E37-F37 -> 1001.45
A38: 260 | B38: Maria College Café | C38: =IFERROR(INDEX('SubDept Single'!G$1:G$100,MATCH('SubDept Sales Report'!A38,'SubDept Single'!A$1:A$100,0)),0) -> 0 | D38: =IFERROR(INDEX('SubDept Coupon (Local Discount)'!G$1:G$100,MATCH('SubDept Sales Report'!A38,'SubDept Coupon (Local Discount)'!A$1:A$100,0)),0) -> 0 | G38: =C38+D38+E54+F54 -> 0
A39: 310 | B39: Cheese | C39: =IFERROR(INDEX('SubDept Single'!G$1:G$100,MATCH('SubDept Sales Report'!A39,'SubDept Single'!A$1:A$100,0)),0) -> 4255.69 | D39: =IFERROR(INDEX('SubDept Coupon (Local Discount)'!G$1:G$100,MATCH('SubDept Sales Report'!A39,'SubDept Coupon (Local Discount)'!A$1:A$100,0)),0) -> 2.23 | E39: =SUMIF('Maria College 1 Sales Data'!D$11:D$2500,A39,'Maria College 1 Sales Data'!G$11:G$2500) -> 0 | F39: =IFERROR(SUMIF('Maria College 2 Sales Data'!D$11:D$2500,A39,'Maria College 2 Sales Data'!G$11:G$2500),0) -> 0 | G39: =(C39+D39)-E39-F39 -> 4257.92
A40: 320 | B40: Meat | C40: =IFERROR(INDEX('SubDept Single'!G$1:G$100,MATCH('SubDept Sales Report'!A40,'SubDept Single'!A$1:A$100,0)),0) -> 6581.59 | D40: =IFERROR(INDEX('SubDept Coupon (Local Discount)'!G$1:G$100,MATCH('SubDept Sales Report'!A40,'SubDept Coupon (Local Discount)'!A$1:A$100,0)),0) -> 0 | E40: =SUMIF('Maria College 1 Sales Data'!D$11:D$2500,A40,'Maria College 1 Sales Data'!G$11:G$2500) -> 0 | F40: =IFERROR(SUMIF('Maria College 2 Sales Data'!D$11:D$2500,A40,'Maria College 2 Sales Data'!G$11:G$2500),0) -> 0 | G40: =(C40+D40)-E40-F40 -> 6581.59
A41: 330 | B41: Specialty Foods | C41: =IFERROR(INDEX('SubDept Single'!G$1:G$100,MATCH('SubDept Sales Report'!A41,'SubDept Single'!A$1:A$100,0)),0) -> 1507.2 | D41: =IFERROR(INDEX('SubDept Coupon (Local Discount)'!G$1:G$100,MATCH('SubDept Sales Report'!A41,'SubDept Coupon (Local Discount)'!A$1:A$100,0)),0) -> 5.5 | E41: =SUMIF('Maria College 1 Sales Data'!D$11:D$2500,A41,'Maria College 1 Sales Data'!G$11:G$2500) -> 0 | F41: =IFERROR(SUMIF('Maria College 2 Sales Data'!D$11:D$2500,A41,'Maria College 2 Sales Data'!G$11:G$2500),0) -> 0 | G41: =(C41+D41)-E41-F41 -> 1512.7
A42: 340 | B42: Fish and Seafood | C42: =IFERROR(INDEX('SubDept Single'!G$1:G$100,MATCH('SubDept Sales Report'!A42,'SubDept Single'!A$1:A$100,0)),0) -> 1743.24 | D42: =IFERROR(INDEX('SubDept Coupon (Local Discount)'!G$1:G$100,MATCH('SubDept Sales Report'!A42,'SubDept Coupon (Local Discount)'!A$1:A$100,0)),0) -> 0 | E42: =SUMIF('Maria College 1 Sales Data'!D$11:D$2500,A42,'Maria College 1 Sales Data'!G$11:G$2500) -> 0 | F42: =IFERROR(SUMIF('Maria College 2 Sales Data'!D$11:D$2500,A42,'Maria College 2 Sales Data'!G$11:G$2500),0) -> 0 | G42: =(C42+D42)-E42-F42 -> 1743.24
A43: 350 | B43: Mercantile-House/Cards/Cals | C43: =IFERROR(INDEX('SubDept Single'!G$1:G$100,MATCH('SubDept Sales Report'!A43,'SubDept Single'!A$1:A$100,0)),0) -> 1036.63 | D43: =IFERROR(INDEX('SubDept Coupon (Local Discount)'!G$1:G$100,MATCH('SubDept Sales Report'!A43,'SubDept Coupon (Local Discount)'!A$1:A$100,0)),0) -> 0 | E43: =SUMIF('Maria College 1 Sales Data'!D$11:D$2500,A43,'Maria College 1 Sales Data'!G$11:G$2500) -> 0 | F43: =IFERROR(SUMIF('Maria College 2 Sales Data'!D$11:D$2500,A43,'Maria College 2 Sales Data'!G$11:G$2500),0) -> 0 | G43: =(C43+D43)-E43-F43 -> 1036.63
A44: 410 | B44: Produce | C44: =IFERROR(INDEX('SubDept Single'!G$1:G$100,MATCH('SubDept Sales Report'!A44,'SubDept Single'!A$1:A$100,0)),0) -> 11352.31 | D44: =IFERROR(INDEX('SubDept Coupon (Local Discount)'!G$1:G$100,MATCH('SubDept Sales Report'!A44,'SubDept Coupon (Local Discount)'!A$1:A$100,0)),0) -> 1.45 | E44: =SUMIF('Maria College 1 Sales Data'!D$11:D$2500,A44,'Maria College 1 Sales Data'!G$11:G$2500) -> 0 | F44: =IFERROR(SUMIF('Maria College 2 Sales Data'!D$11:D$2500,A44,'Maria College 2 Sales Data'!G$11:G$2500),0) -> 0 | G44: =(C44+D44)-E44-F44 -> 11353.76
A45: 420 | B45: Plants & Gardening | C45: =IFERROR(INDEX('SubDept Single'!G$1:G$100,MATCH('SubDept Sales Report'!A45,'SubDept Single'!A$1:A$100,0)),0) -> 873.56 | D45: =IFERROR(INDEX('SubDept Coupon (Local Discount)'!G$1:G$100,MATCH('SubDept Sales Report'!A45,'SubDept Coupon (Local Discount)'!A$1:A$100,0)),0) -> 0 | E45: =SUMIF('Maria College 1 Sales Data'!D$11:D$2500,A45,'Maria College 1 Sales Data'!G$11:G$2500) -> 0 | F45: =IFERROR(SUMIF('Maria College 2 Sales Data'!D$11:D$2500,A45,'Maria College 2 Sales Data'!G$11:G$2500),0) -> 0 | G45: =(C45+D45)-E45-F45 -> 873.56
A46: 510 | B46: BodyCare (Tax) | C46: =IFERROR(INDEX('SubDept Single'!G$1:G$100,MATCH('SubDept Sales Report'!A46,'SubDept Single'!A$1:A$100,0)),0) -> 2292.97 | D46: =IFERROR(INDEX('SubDept Coupon (Local Discount)'!G$1:G$100,MATCH('SubDept Sales Report'!A46,'SubDept Coupon (Local Discount)'!A$1:A$100,0)),0) -> 0.17 | E46: =SUMIF('Maria College 1 Sales Data'!D$11:D$2500,A46,'Maria College 1 Sales Data'!G$11:G$2500) -> 0 | F46: =IFERROR(SUMIF('Maria College 2 Sales Data'!D$11:D$2500,A46,'Maria College 2 Sales Data'!G$11:G$2500),0) -> 0 | G46: =(C46+D46)-E46-F46 -> 2293.14
A47: 520 | B47: Supplements | C47: =IFERROR(INDEX('SubDept Single'!G$1:G$100,MATCH('SubDept Sales Report'!A47,'SubDept Single'!A$1:A$100,0)),0) -> 5161.2 | D47: =IFERROR(INDEX('SubDept Coupon (Local Discount)'!G$1:G$100,MATCH('SubDept Sales Report'!A47,'SubDept Coupon (Local Discount)'!A$1:A$100,0)),0) -> 1.35 | E47: =SUMIF('Maria College 1 Sales Data'!D$11:D$2500,A47,'Maria College 1 Sales Data'!G$11:G$2500) -> 0 | F47: =IFERROR(SUMIF('Maria College 2 Sales Data'!D$11:D$2500,A47,'Maria College 2 Sales Data'!G$11:G$2500),0) -> 0 | G47: =(C47+D47)-E47-F47 -> 5162.55
A48: 530 | B48: Herbs | C48: =IFERROR(INDEX('SubDept Single'!G$1:G$100,MATCH('SubDept Sales Report'!A48,'SubDept Single'!A$1:A$100,0)),0) -> 0 | D48: =IFERROR(INDEX('SubDept Coupon (Local Discount)'!G$1:G$100,MATCH('SubDept Sales Report'!A48,'SubDept Coupon (Local Discount)'!A$1:A$100,0)),0) -> 0 | E48: =SUMIF('Maria College 1 Sales Data'!D$11:D$2500,A48,'Maria College 1 Sales Data'!G$11:G$2500) -> 0 | F48: =IFERROR(SUMIF('Maria College 2 Sales Data'!D$11:D$2500,A48,'Maria College 2 Sales Data'!G$11:G$2500),0) -> 0 | G48: =(C48+D48)-E48-F48 -> 0
A49: 540 | B49: Books | C49: =IFERROR(INDEX('SubDept Single'!G$1:G$100,MATCH('SubDept Sales Report'!A49,'SubDept Single'!A$1:A$100,0)),0) -> 0 | D49: =IFERROR(INDEX('SubDept Coupon (Local Discount)'!G$1:G$100,MATCH('SubDept Sales Report'!A49,'SubDept Coupon (Local Discount)'!A$1:A$100,0)),0) -> 0 | E49: =SUMIF('Maria College 1 Sales Data'!D$11:D$2500,A49,'Maria College 1 Sales Data'!G$11:G$2500) -> 0 | F49: =IFERROR(SUMIF('Maria College 2 Sales Data'!D$11:D$2500,A49,'Maria College 2 Sales Data'!G$11:G$2500),0) -> 0 | G49: =(C49+D49)-E49-F49 -> 0
A50: 550 | B50: Magazines | C50: =IFERROR(INDEX('SubDept Single'!G$1:G$100,MATCH('SubDept Sales Report'!A50,'SubDept Single'!A$1:A$100,0)),0) -> 0 | D50: =IFERROR(INDEX('SubDept Coupon (Local Discount)'!G$1:G$100,MATCH('SubDept Sales Report'!A50,'SubDept Coupon (Local Discount)'!A$1:A$100,0)),0) -> 0 | E50: =SUMIF('Maria College 1 Sales Data'!D$11:D$2500,A50,'Maria College 1 Sales Data'!G$11:G$2500) -> 0 | F50: =IFERROR(SUMIF('Maria College 2 Sales Data'!D$11:D$2500,A50,'Maria College 2 Sales Data'!G$11:G$2500),0) -> 0 | G50: =(C50+D50)-E50-F50 -> 0
...

Sheet 82026 discounts
A1: Discounts by Shopper Level
A2: Date: | B2: 8/20/2026 | C2: to | D2: 8/20/2026
A3: Target: | B3: RAL | C3: Report all
C4: Description | I4: Qty | J4: Amount | K4: Other
A5: Shareholder | D5: 2 | H5: 2715 | I5: 307.31
A6: Senior NonMember | D6: 3 | H6: 753 | I6: 95.59
A7: Senior Share | D7: 4 | H7: 1329 | I7: 382.76
A8: Monthly Worker | D8: 5 | H8: 104 | I8: 48.98
A9: Weekly Worker | D9: 6 | H9: 1723 | I9: 2301.82
A10: Employee | D10: 7 | H10: 576 | I10: 742.25
A11: Visiting Co-op | D11: 8 | H11: 59 | I11: 6.27
A12: Vendor/Business | D12: 9 | H12: 47 | I12: 17.02
A13: Non Profit | D13: 19 | H13: 3 | I13: 3.3
C14: Grand Total
C15: Member Discounts | H15: 7309 | I15: 3905.3
A16: HONEST WEIGHT FOOD | H16: Printed : | I16: 8/21/2026 10:57:14 AM | L16: Page 1

Sheet 82026 bs
A1: Store Balance Sheet
A2: Date: 8/20/2026 to 8/20/2026
A3: Target: RAL Report all
C4: Description | F4: Amount | H4: Balance | J4: Debit | K4: Credit
A5: 10 | B5: BULK TOTAL | D5: 0 | E5: 8950.04 | G5: C | K5: 8950.04
A6: 20 | B6: PRODUCE TOTAL | D6: 0 | E6: 12227.32 | G6: C | K6: 12227.32
A7: 30 | B7: GROCERY TOTAL | D7: 0 | E7: 28926.01 | G7: C | K7: 28926.01
A8: 40 | B8: CHEESE TOTAL | D8: 0 | E8: 6807.25 | G8: C | K8: 6807.25
A9: 50 | B9: PROMO | D9: 0 | E9: 158.84 | G9: C | K9: 158.84
A10: 60 | B10: WELLNESS | D10: 0 | E10: 7455.69 | G10: C | K10: 7455.69
A11: 70 | B11: MISC. TRANSACTIONS | D11: 0 | E11: 298.56 | G11: C | K11: 298.56
A12: 80 | B12: MEAT & FISH | D12: 0 | E12: 8324.83 | G12: C | K12: 8324.83
A13: 90 | B13: PREPARED FOODS (DELI) | D13: 0 | E13: 15002.14 | G13: C | K13: 15002.14
A14: 120 | B14: STORE COUPONS | D14: 0 | E14: -684.02 | G14: C | K14: -684.02
A15: 130 | B15: STORE SUPPLIES | D15: 0 | E15: 9.55 | G15: C | K15: 9.55
B16: Coupon distribution | E16: -63.33 | I16: 63.33
A17: 3 | B17: Net Sales | E17: 87412.88 | G17: C
B18: Total | C18: Sales | E18: = | F18: 87476.21 | H18: 87412.88
A19: 9 | B19: Member Discounts | E19: 3905.3 | G19: D | J19: 3905.3
B20: Total | C20: Global Discount | E20: = | F20: 87476.21 | H20: 3905.3
A21: 22 | B21: Tax 1 | E21: 1267.45 | G21: C | K21: 1267.45
A22: 26 | B22: Tax 2 | E22: 5.41 | G22: C | K22: 5.41
A23: 30 | B23: Tax 3 | E23: 0.72 | G23: C | K23: 0.72
B24: Total | C24: Taxes | E24: = | F24: 262428.63 | H24: 1273.58
A25: 39 | B25: Bottle sales | E25: 49.3 | G25: C | K25: 49.3
A26: 40 | B26: Milk Bottle fee | E26: 78 | G26: C | K26: 78
B27: Total | C27: Plus | E27: = | F27: 174952.42 | H27: 127.3
A28: 205 | B28: Charity | E28: 178.1 | G28: C | K28: 178.1
A29: 207 | B29: Nickel Round Up/Down | E29: 0.13 | G29: C | K29: 0.13
A30: 208 | B30: Prepaid increase | E30: 1483.2 | G30: C | K30: 1483.2
B31: Total | C31: Received | E31: = | F31: 262428.63 | H31: 1661.43
A32: 901 | B32: Rev. Cash | E32: 8623.61
A33: 902 | B33: Rev. Check | E33: 52
A34: 922 | B34: Rev. Donation | E34: 140
A35: 903 | B35: Rev. Debit card | E35: 20276.92
I36: Printed : | J36: 8/21/2026 10:57:30 AM | L36: Page 1
A37: Store Balance Sheet
A38: Date: 8/20/2026 to 8/20/2026
A39: Target: RAL Report all
C40: Description | F40: Amount | H40: Balance | J40: Debit | K40: Credit
...
