Workbook

Sheet Membership Payment Plans
O14: *If paid off in 3 months we remove the interest
O15: What about 5 year?

Sheet InHouse Purchases
A1: PURCHASE | C1: EXPENSE ACCOUNT
A4: Plants Dept - Water/Drinks | C4: Member Appreciation
A5: Chill Room-Water/Snacks | C5: Staff Appreciation
A6: Grocery Cart Returns | C6: Maint - Equip
A7: Parking | C7: 8424000 · Admn -Travel Transportation Exp
A8: Snap Initiative | C8: Admin Miscellaneous expense
A21: Building Block | C21: S:\Finance & Payroll Forms\Finance Work Files\Building Blocks

Sheet Random Sales
A1: RANDOM SALE | B1: ACCOUNT TO CREDIT
A2: Books | B2: Magazines
A3: Candles/Incense | B3: Mercantile
A4: Coop Scoop | B4: Look up code to left (usually CDTA Bus Passes)
A5: CDTA Bus Passes | B5: Promotional Sales

Sheet SMS Look Up
A1: Member Shares | B1: Journal>Totalizers>Totalizer> Change Date> 3420

Sheet SubDept Single
A1: 27 | B1: Store coupons | F1: -1 | G1: -428
A2: 28 | B2: Store Supplies | F2: 41 | G2: 4.1
A3: 38 | B3: NYS-Alb Cty Bags | F3: 42 | G3: 2.1
A4: 110 | B4: Grocery Non-Tax | F4: 2867 | G4: 13650.9
A5: 120 | B5: Refrigerated | F5: 2022 | G5: 9879.79
A6: 130 | B6: Frozen Foods | F6: 495 | G6: 3204.66
A7: 140 | B7: Bulk | F7: 1288 | G7: 9635.59
A8: 142 | B8: Bulk Teas/Spices | F8: 133 | G8: 611.62
A9: 150 | B9: Bread and Bakery | F9: 385 | G9: 2209.46
A10: 160 | B10: Beer/Alcohol | F10: 64 | G10: 588.27
A11: 180 | B11: Pet Supplies | F11: 60 | G11: 184.08
A12: 190 | B12: General Merchandise | F12: 114 | G12: 703.16
... A28: 1300 | B28: Promotional | F28: 16 | G28: 111.9

Sheet SubDept Coupon (Local Discount)
A1: 110 | B1: Grocery Non-Tax | F1: 23 | G1: 14.02
A2: 120 | B2: Refrigerated | F2: 54 | G2: 28.45
A3: 130 | B3: Frozen Foods | F3: 3 | G3: 2.23
A4: 140 | B4: Bulk | F4: 3 | G4: 6.37
A5: 142 | B5: Bulk Teas/Spices | F5: 108
A6: 150 | B6: Bread and Bakery | F6: 42 | G6: 18.71
A7: 160 | B7: Beer/Alcohol | F7: 3 | G7: 2.49
A8: 210 | B8: In House Deli | F8: 17
A9: 220 | B9: In House Bakery | F9: 4 | G9: 2.95
A10: 310 | B10: Cheese | F10: 2 | G10: 1.14
A11: 330 | B11: Specialty Foods | F11: 2 | G11: 2.63
A12: 350 | B12: Mercantile-House/Cards/Cals | F12: 1 | G12: 1.1
A13: 410 | B13: Produce | F13: 4 | G13: 1.4
A14: 420 | B14: Plants & Gardening | F14: 1 | G14: 8.39

Sheet Maria College 1 Sales Data

Sheet Maria College 2 Sales Data

Sheet SubDept Sales Report
A1: Sub-Dept. Single Total Report | I1: Store Coupons: | J1: =G10 -> -428 | L1: Milk Bottles Returns | M1: =20+12+16 -> 48 | O1: Refunded Discounts
I2: Owner Apprec. (5%) Total: | J2: =D54*-1 -> -89.88 | L2: Store Coupons | M2: =J1+M1 -> -380 | O2: Bunnies
I3: Sales Total: | J3: =G54+J1+J2 -> 95881.78 | O3: Pass Through Donations
A4: Sub-Dept. Number | B4: Sub-Dept. | C4: Sales Total | D4: Coupon Total | E4: Maria 1 Sales | F4: Maria 2 Sales | G4: Sub-Dept. Single Total | O4: Total | P4: =SUM(P1:P3) -> 0
A5: 22 | B5: Coop Scoop Ad payment | C5: =IFERROR(INDEX('SubDept Single'!G$1:G$100,MATCH('SubDept Sales Report'!A5,'SubDept Single'!A$1:A$100,0)),0) -> 0 | D5: =IFERROR(INDEX('SubDept Coupon (Local Discount)'!G$1:G$100,MATCH('SubDept Sales Report'!A5,'SubDept Coupon (Local Discount)'!A$1:A$100,0)),0) -> 0 | E5: =IFERROR(SUMIF('Maria College 1 Sales Data'!D$11:D$2500,A5,'Maria College 1 Sales Data'!G$11:G$2500),0) -> 0 | F5: =IFERROR(SUMIF('Maria College 2 Sales Data'!D$11:D$2500,A5,'Maria College 2 Sales Data'!G$11:G$2500),0) -> 0 | G5: =(C5+D5)-E5-F5 -> 0
A6: 23 | B6: Refunded Discounts | C6: =IFERROR(INDEX('SubDept Single'!G$1:G$100,MATCH('SubDept Sales Report'!A6,'SubDept Single'!A$1:A$100,0)),0) -> 0 | D6: =IFERROR(INDEX('SubDept Coupon (Local Discount)'!G$1:G$100,MATCH('SubDept Sales Report'!A6,'SubDept Coupon (Local Discount)'!A$1:A$100,0)),0) -> 0 | E6: =SUMIF('Maria College 1 Sales Data'!D$11:D$2500,A6,'Maria College 1 Sales Data'!G$11:G$2500) -> 0 | F6: =IFERROR(SUMIF('Maria College 2 Sales Data'!D$11:D$2500,A6,'Maria College 2 Sales Data'!G$11:G$2500),0) -> 0 | G6: =(C6+D6)-E6-F6 -> 0
A7: 24 | B7: bottle deposits | C7: =IFERROR(INDEX('SubDept Single'!G$1:G$100,MATCH('SubDept Sales Report'!A7,'SubDept Single'!A$1:A$100,0)),0) -> 0 | D7: =IFERROR(INDEX('SubDept Coupon (Local Discount)'!G$1:G$100,MATCH('SubDept Sales Report'!A7,'SubDept Coupon (Local Discount)'!A$1:A$100,0)),0) -> 0 | E7: =SUMIF('Maria College 1 Sales Data'!D$11:D$2500,A7,'Maria College 1 Sales Data'!G$11:G$2500) -> 0 | F7: =IFERROR(SUMIF('Maria College 2 Sales Data'!D$11:D$2500,A7,'Maria College 2 Sales Data'!G$11:G$2500),0) -> 0 | G7: =(C7+D7)-E7-F7 -> 0
A8: 25 | B8: gift certificates | C8: =IFERROR(INDEX('SubDept Single'!G$1:G$100,MATCH('SubDept Sales Report'!A8,'SubDept Single'!A$1:A$100,0)),0) -> 0 | D8: =IFERROR(INDEX('SubDept Coupon (Local Discount)'!G$1:G$100,MATCH('SubDept Sales Report'!A8,'SubDept Coupon (Local Discount)'!A$1:A$100,0)),0) -> 0 | E8: =SUMIF('Maria College 1 Sales Data'!D$11:D$2500,A8,'Maria College 1 Sales Data'!G$11:G$2500) -> 0 | F8: =IFERROR(SUMIF('Maria College 2 Sales Data'!D$11:D$2500,A8,'Maria College 2 Sales Data'!G$11:G$2500),0) -> 0 | G8: =(C8+D8)-E8-F8 -> 0
A9: 26 | B9: SHARE PAYMENT | C9: =IFERROR(INDEX('SubDept Single'!G$1:G$100,MATCH('SubDept Sales Report'!A9,'SubDept Single'!A$1:A$100,0)),0) -> 0 | D9: =IFERROR(INDEX('SubDept Coupon (Local Discount)'!G$1:G$100,MATCH('SubDept Sales Report'!A9,'SubDept Coupon (Local Discount)'!A$1:A$100,0)),0) -> 0 | E9: =SUMIF('Maria College 1 Sales Data'!D$11:D$2500,A9,'Maria College 1 Sales Data'!G$11:G$2500) -> 0 | F9: =IFERROR(SUMIF('Maria College 2 Sales Data'!D$11:D$2500,A9,'Maria College 2 Sales Data'!G$11:G$2500),0) -> 0 | G9: =(C9+D9)-E9-F9 -> 0
A10: 27 | B10: Store coupons | C10: =IFERROR(INDEX('SubDept Single'!G$1:G$100,MATCH('SubDept Sales Report'!A10,'SubDept Single'!A$1:A$100,0)),0) -> -428 | D10: =IFERROR(INDEX('SubDept Coupon (Local Discount)'!G$1:G$100,MATCH('SubDept Sales Report'!A10,'SubDept Coupon (Local Discount)'!A$1:A$100,0)),0) -> 0 | E10: 0 | F10: 0 | G10: =C10+D10 -> -428
A11: 28 | B11: Store Supplies | C11: =IFERROR(INDEX('SubDept Single'!G$1:G$100,MATCH('SubDept Sales Report'!A11,'SubDept Single'!A$1:A$100,0)),0) -> 4.1 | D11: =IFERROR(INDEX('SubDept Coupon (Local Discount)'!G$1:G$100,MATCH('SubDept Sales Report'!A11,'SubDept Coupon (Local Discount)'!A$1:A$100,0)),0) -> 0 | E11: =SUMIF('Maria College 1 Sales Data'!D$11:D$2500,A11,'Maria College 1 Sales Data'!G$11:G$2500) -> 0 | F11: =IFERROR(SUMIF('Maria College 2 Sales Data'!D$11:D$2500,A11,'Maria College 2 Sales Data'!G$11:G$2500),0) -> 0 | G11: =(C11+D11)-E11-F11 -> 4.1
A12: 29 | B12: Building Blocks | C12: =IFERROR(INDEX('SubDept Single'!G$1:G$100,MATCH('SubDept Sales Report'!A12,'SubDept Single'!A$1:A$100,0)),0) -> 0 | D12: =IFERROR(INDEX('SubDept Coupon (Local Discount)'!G$1:G$100,MATCH('SubDept Sales Report'!A12,'SubDept Coupon (Local Discount)'!A$1:A$100,0)),0) -> 0 | E12: =SUMIF('Maria College 1 Sales Data'!D$11:D$2500,A12,'Maria College 1 Sales Data'!G$11:G$2500) -> 0 | F12: =IFERROR(SUMIF('Maria College 2 Sales Data'!D$11:D$2500,A12,'Maria College 2 Sales Data'!G$11:G$2500),0) -> 0 | G12: =(C12+D12)-E12-F12 -> 0
A13: 30 | B13: Groupon | C13: =IFERROR(INDEX('SubDept Single'!G$1:G$100,MATCH('SubDept Sales Report'!A13,'SubDept Single'!A$1:A$100,0)),0) -> 0 | D13: =IFERROR(INDEX('SubDept Coupon (Local Discount)'!G$1:G$100,MATCH('SubDept Sales Report'!A13,'SubDept Coupon (Local Discount)'!A$1:A$100,0)),0) -> 0 | E13: =SUMIF('Maria College 1 Sales Data'!D$11:D$2500,A13,'Maria College 1 Sales Data'!G$11:G$2500) -> 0 | F13: =IFERROR(SUMIF('Maria College 2 Sales Data'!D$11:D$2500,A13,'Maria College 2 Sales Data'!G$11:G$2500),0) -> 0 | G13: =(C13+D13)-E13-F13 -> 0
A14: 31 | B14: Crowd Savings | C14: =IFERROR(INDEX('SubDept Single'!G$1:G$100,MATCH('SubDept Sales Report'!A14,'SubDept Single'!A$1:A$100,0)),0) -> 0 | D14: =IFERROR(INDEX('SubDept Coupon (Local Discount)'!G$1:G$100,MATCH('SubDept Sales Report'!A14,'SubDept Coupon (Local Discount)'!A$1:A$100,0)),0) -> 0 | E14: =SUMIF('Maria College 1 Sales Data'!D$11:D$2500,A14,'Maria College 1 Sales Data'!G$11:G$2500) -> 0 | F14: =IFERROR(SUMIF('Maria College 2 Sales Data'!D$11:D$2500,A14,'Maria College 2 Sales Data'!G$11:G$2500),0) -> 0 | G14: =(C14+D14)-E14-F14 -> 0
A15: 32 | B15: PASS THROUGH DONATIONS | C15: =IFERROR(INDEX('SubDept Single'!G$1:G$100,MATCH('SubDept Sales Report'!A15,'SubDept Single'!A$1:A$100,0)),0) -> 0 | D15: =IFERROR(INDEX('SubDept Coupon (Local Discount)'!G$1:G$100,MATCH('SubDept Sales Report'!A15,'SubDept Coupon (Local Discount)'!A$1:A$100,0)),0) -> 0 | E15: =SUMIF('Maria College 1 Sales Data'!D$11:D$2500,A15,'Maria College 1 Sales Data'!G$11:G$2500) -> 0 | F15: =IFERROR(SUMIF('Maria College 2 Sales Data'!D$11:D$2500,A15,'Maria College 2 Sales Data'!G$11:G$2500),0) -> 0 | G15: =(C15+D15)-E15-F15 -> 0
A16: 33 | B16: Bag Credits | C16: =IFERROR(INDEX('SubDept Single'!G$1:G$100,MATCH('SubDept Sales Report'!A16,'SubDept Single'!A$1:A$100,0)),0) -> 0 | D16: =IFERROR(INDEX('SubDept Coupon (Local Discount)'!G$1:G$100,MATCH('SubDept Sales Report'!A16,'SubDept Coupon (Local Discount)'!A$1:A$100,0)),0) -> 0 | E16: =SUMIF('Maria College 1 Sales Data'!D$11:D$2500,A16,'Maria College 1 Sales Data'!G$11:G$2500) -> 0 | F16: =IFERROR(SUMIF('Maria College 2 Sales Data'!D$11:D$2500,A16,'Maria College 2 Sales Data'!G$11:G$2500),0) -> 0 | G16: =(C16+D16)-E16-F16 -> 0
A17: 34 | B17: PAID-INS | C17: =IFERROR(INDEX('SubDept Single'!G$1:G$100,MATCH('SubDept Sales Report'!A17,'SubDept Single'!A$1:A$100,0)),0) -> 0 | D17: =IFERROR(INDEX('SubDept Coupon (Local Discount)'!G$1:G$100,MATCH('SubDept Sales Report'!A17,'SubDept Coupon (Local Discount)'!A$1:A$100,0)),0) -> 0 | E17: =SUMIF('Maria College 1 Sales Data'!D$11:D$2500,A17,'Maria College 1 Sales Data'!G$11:G$2500) -> 0 | F17: =IFERROR(SUMIF('Maria College 2 Sales Data'!D$11:D$2500,A17,'Maria College 2 Sales Data'!G$11:G$2500),0) -> 0 | G17: =(C17+D17)-E17-F17 -> 0
A18: 35 | B18: Owner Appreciation 5% | C18: =IFERROR(INDEX('SubDept Single'!G$1:G$100,MATCH('SubDept Sales Report'!A18,'SubDept Single'!A$1:A$100,0)),0) -> 0 | D18: =IFERROR(INDEX('SubDept Coupon (Local Discount)'!G$1:G$100,MATCH('SubDept Sales Report'!A18,'SubDept Coupon (Local Discount)'!A$1:A$100,0)),0) -> 0 | E18: =SUMIF('Maria College 1 Sales Data'!D$11:D$2500,A18,'Maria College 1 Sales Data'!G$11:G$2500) -> 0 | F18: =IFERROR(SUMIF('Maria College 2 Sales Data'!D$11:D$2500,A18,'Maria College 2 Sales Data'!G$11:G$2500),0) -> 0 | G18: =(C18+D18)-E18-F18 -> 0
A19: 37 | B19: TESTStaff Appreciation | C19: =IFERROR(INDEX('SubDept Single'!G$1:G$100,MATCH('SubDept Sales Report'!A19,'SubDept Single'!A$1:A$100,0)),0) -> 0 | D19: =IFERROR(INDEX('SubDept Coupon (Local Discount)'!G$1:G$100,MATCH('SubDept Sales Report'!A19,'SubDept Coupon (Local Discount)'!A$1:A$100,0)),0) -> 0 | E19: =SUMIF('Maria College 1 Sales Data'!D$11:D$2500,A19,'Maria College 1 Sales Data'!G$11:G$2500) -> 0 | F19: =IFERROR(SUMIF('Maria College 2 Sales Data'!D$11:D$2500,A19,'Maria College 2 Sales Data'!G$11:G$2500),0) -> 0 | G19: =(C19+D19)-E19-F19 -> 0
A20: 38 | B20: NYS-Alb Cty Bags | C20: =IFERROR(INDEX('SubDept Single'!G$1:G$100,MATCH('SubDept Sales Report'!A20,'SubDept Single'!A$1:A$100,0)),0) -> 2.1 | D20: =IFERROR(INDEX('SubDept Coupon (Local Discount)'!G$1:G$100,MATCH('SubDept Sales Report'!A20,'SubDept Coupon (Local Discount)'!A$1:A$100,0)),0) -> 0 | E20: =SUMIF('Maria College 1 Sales Data'!D$11:D$2500,A20,'Maria College 1 Sales Data'!G$11:G$2500) -> 0 | F20: =IFERROR(SUMIF('Maria College 2 Sales Data'!D$11:D$2500,A20,'Maria College 2 Sales Data'!G$11:G$2500),0) -> 0 | G20: =(C20+D20)-E20-F20 -> 2.1
A21: 50 | B21: ENVIROTOKENS | C21: =IFERROR(INDEX('SubDept Single'!G$1:G$100,MATCH('SubDept Sales Report'!A21,'SubDept Single'!A$1:A$100,0)),0) -> 0 | D21: =IFERROR(INDEX('SubDept Coupon (Local Discount)'!G$1:G$100,MATCH('SubDept Sales Report'!A21,'SubDept Coupon (Local Discount)'!A$1:A$100,0)),0) -> 0 | E21: =SUMIF('Maria College 1 Sales Data'!D$11:D$2500,A21,'Maria College 1 Sales Data'!G$11:G$2500) -> 0 | F21: =IFERROR(SUMIF('Maria College 2 Sales Data'!D$11:D$2500,A21,'Maria College 2 Sales Data'!G$11:G$2500),0) -> 0 | G21: =(C21+D21)-E21-F21 -> 0
A22: 110 | B22: Grocery Non-Tax | C22: =IFERROR(INDEX('SubDept Single'!G$1:G$100,MATCH('SubDept Sales Report'!A22,'SubDept Single'!A$1:A$100,0)),0) -> 13650.9 | D22: =IFERROR(INDEX('SubDept Coupon (Local Discount)'!G$1:G$100,MATCH('SubDept Sales Report'!A22,'SubDept Coupon (Local Discount)'!A$1:A$100,0)),0) -> 14.02 | E22: =SUMIF('Maria College 1 Sales Data'!D$11:D$2500,A22,'Maria College 1 Sales Data'!G$11:G$2500) -> 0 | F22: =IFERROR(SUMIF('Maria College 2 Sales Data'!D$11:D$2500,A22,'Maria College 2 Sales Data'!G$11:G$2500),0) -> 0 | G22: =(C22+D22)-E22-F22 -> 13664.92
... A33: 220 | B33: In House Bakery | C33: =IFERROR(INDEX('SubDept Single'!G$1:G$100,MATCH('SubDept Sales Report'!A33,'SubDept Single'!A$1:A$100,0)),0) -> 2272.84 | D33: =IFERROR(INDEX('SubDept Coupon (Local Discount)'!G$1:G$100,MATCH('SubDept Sales Report'!A33,'SubDept Coupon (Local Discount)'!A$1:A$100,0)),0) -> 2.95 | E33: =SUMIF('Maria College 1 Sales Data'!D$11:D$2500,A33,'Maria College 1 Sales Data'!G$11:G$2500) -> 0 | F33: =IFERROR(SUMIF('Maria College 2 Sales Data'!D$11:D$2500,A33,'Maria College 2 Sales Data'!G$11:G$2500),0) -> 0 | G33: =(C33+D33)-E33-F33 -> 2275.79
A34: 230 | B34: Catering | C34: =IFERROR(INDEX('SubDept Single'!G$1:G$100,MATCH('SubDept Sales Report'!A34,'SubDept Single'!A$1:A$100,0)),0) -> 0 | D34: =IFERROR(INDEX('SubDept Coupon (Local Discount)'!G$1:G$100,MATCH('SubDept Sales Report'!A34,'SubDept Coupon (Local Discount)'!A$1:A$100,0)),0) -> 0 | E34: 0 | F34: 0 | G34: =C34+D34 -> 0
A35: 235 | B35: Sushi | C35: =IFERROR(INDEX('SubDept Single'!G$1:G$100,MATCH('SubDept Sales Report'!A35,'SubDept Single'!A$1:A$100,0)),0) -> 542.55 | D35: =IFERROR(INDEX('SubDept Coupon (Local Discount)'!G$1:G$100,MATCH('SubDept Sales Report'!A35,'SubDept Coupon (Local Discount)'!A$1:A$100,0)),0) -> 0 | E35: =SUMIF('Maria College 1 Sales Data'!D$11:D$2500,A35,'Maria College 1 Sales Data'!G$11:G$2500) -> 0 | F35: =IFERROR(SUMIF('Maria College 2 Sales Data'!D$11:D$2500,A35,'Maria College 2 Sales Data'!G$11:G$2500),0) -> 0 | G35: =(C35+D35)-E35-F35 -> 542.55
A36: 240 | B36: Java & Juice | C36: =IFERROR(INDEX('SubDept Single'!G$1:G$100,MATCH('SubDept Sales Report'!A36,'SubDept Single'!A$1:A$100,0)),0) -> 766.1 | D36: =IFERROR(INDEX('SubDept Coupon (Local Discount)'!G$1:G$100,MATCH('SubDept Sales Report'!A36,'SubDept Coupon (Local Discount)'!A$1:A$100,0)),0) -> 0 | E36: =SUMIF('Maria College 1 Sales Data'!D$11:D$2500,A36,'Maria College 1 Sales Data'!G$11:G$2500) -> 0 | F36: =IFERROR(SUMIF('Maria College 2 Sales Data'!D$11:D$2500,A36,'Maria College 2 Sales Data'!G$11:G$2500),0) -> 0 | G36: =(C36+D36)-E36-F36 -> 766.1
A37: 250 | B37: ESP - Co-op Cafe | C37: =IFERROR(INDEX('SubDept Single'!G$1:G$100,MATCH('SubDept Sales Report'!A37,'SubDept Single'!A$1:A$100,0)),0) -> 815.73 | D37: =IFERROR(INDEX('SubDept Coupon (Local Discount)'!G$1:G$100,MATCH('SubDept Sales Report'!A37,'SubDept Coupon (Local Discount)'!A$1:A$100,0)),0) -> 0 | E37: =SUMIF('Maria College 1 Sales Data'!D$11:D$2500,A37,'Maria College 1 Sales Data'!G$11:G$2500) -> 0 | F37: =IFERROR(SUMIF('Maria College 2 Sales Data'!D$11:D$2500,A37,'Maria College 2 Sales Data'!G$11:G$2500),0) -> 0 | G37: =(C37+D37)-E37-F37 -> 815.73
A38: 260 | B38: Maria College Café | C38: =IFERROR(INDEX('SubDept Single'!G$1:G$100,MATCH('SubDept Sales Report'!A38,'SubDept Single'!A$1:A$100,0)),0) -> 0 | D38: =IFERROR(INDEX('SubDept Coupon (Local Discount)'!G$1:G$100,MATCH('SubDept Sales Report'!A38,'SubDept Coupon (Local Discount)'!A$1:A$100,0)),0) -> 0 | G38: =C38+D38+E54+F54 -> 0
A39: 310 | B39: Cheese | C39: =IFERROR(INDEX('SubDept Single'!G$1:G$100,MATCH('SubDept Sales Report'!A39,'SubDept Single'!A$1:A$100,0)),0) -> 3970.27 | D39: =IFERROR(INDEX('SubDept Coupon (Local Discount)'!G$1:G$100,MATCH('SubDept Sales Report'!A39,'SubDept Coupon (Local Discount)'!A$1:A$100,0)),0) -> 1.14 | E39: =SUMIF('Maria College 1 Sales Data'!D$11:D$2500,A39,'Maria College 1 Sales Data'!G$11:G$2500) -> 0 | F39: =IFERROR(SUMIF('Maria College 2 Sales Data'!D$11:D$2500,A39,'Maria College 2 Sales Data'!G$11:G$2500),0) -> 0 | G39: =(C39+D39)-E39-F39 -> 3971.41
A40: 320 | B40: Meat | C40: =IFERROR(INDEX('SubDept Single'!G$1:G$100,MATCH('SubDept Sales Report'!A40,'SubDept Single'!A$1:A$100,0)),0) -> 7897.93 | D40: =IFERROR(INDEX('SubDept Coupon (Local Discount)'!G$1:G$100,MATCH('SubDept Sales Report'!A40,'SubDept Coupon (Local Discount)'!A$1:A$100,0)),0) -> 0 | E40: =SUMIF('Maria College 1 Sales Data'!D$11:D$2500,A40,'Maria College 1 Sales Data'!G$11:G$2500) -> 0 | F40: =IFERROR(SUMIF('Maria College 2 Sales Data'!D$11:D$2500,A40,'Maria College 2 Sales Data'!G$11:G$2500),0) -> 0 | G40: =(C40+D40)-E40-F40 -> 7897.93
A41: 330 | B41: Specialty Foods | C41: =IFERROR(INDEX('SubDept Single'!G$1:G$100,MATCH('SubDept Sales Report'!A41,'SubDept Single'!A$1:A$100,0)),0) -> 2196.71 | D41: =IFERROR(INDEX('SubDept Coupon (Local Discount)'!G$1:G$100,MATCH('SubDept Sales Report'!A41,'SubDept Coupon (Local Discount)'!A$1:A$100,0)),0) -> 2.63 | E41: =SUMIF('Maria College 1 Sales Data'!D$11:D$2500,A41,'Maria College 1 Sales Data'!G$11:G$2500) -> 0 | F41: =IFERROR(SUMIF('Maria College 2 Sales Data'!D$11:D$2500,A41,'Maria College 2 Sales Data'!G$11:G$2500),0) -> 0 | G41: =(C41+D41)-E41-F41 -> 2199.34
A42: 340 | B42: Fish and Seafood | C42: =IFERROR(INDEX('SubDept Single'!G$1:G$100,MATCH('SubDept Sales Report'!A42,'SubDept Single'!A$1:A$100,0)),0) -> 1868.01 | D42: =IFERROR(INDEX('SubDept Coupon (Local Discount)'!G$1:G$100,MATCH('SubDept Sales Report'!A42,'SubDept Coupon (Local Discount)'!A$1:A$100,0)),0) -> 0 | E42: =SUMIF('Maria College 1 Sales Data'!D$11:D$2500,A42,'Maria College 1 Sales Data'!G$11:G$2500) -> 0 | F42: =IFERROR(SUMIF('Maria College 2 Sales Data'!D$11:D$2500,A42,'Maria College 2 Sales Data'!G$11:G$2500),0) -> 0 | G42: =(C42+D42)-E42-F42 -> 1868.01
A43: 350 | B43: Mercantile-House/Cards/Cals | C43: =IFERROR(INDEX('SubDept Single'!G$1:G$100,MATCH('SubDept Sales Report'!A43,'SubDept Single'!A$1:A$100,0)),0) -> 1087.41 | D43: =IFERROR(INDEX('SubDept Coupon (Local Discount)'!G$1:G$100,MATCH('SubDept Sales Report'!A43,'SubDept Coupon (Local Discount)'!A$1:A$100,0)),0) -> 1.1 | E43: =SUMIF('Maria College 1 Sales Data'!D$11:D$2500,A43,'Maria College 1 Sales Data'!G$11:G$2500) -> 0 | F43: =IFERROR(SUMIF('Maria College 2 Sales Data'!D$11:D$2500,A43,'Maria College 2 Sales Data'!G$11:G$2500),0) -> 0 | G43: =(C43+D43)-E43-F43 -> 1088.51
A44: 410 | B44: Produce | C44: =IFERROR(INDEX('SubDept Single'!G$1:G$100,MATCH('SubDept Sales Report'!A44,'SubDept Single'!A$1:A$100,0)),0) -> 15454.88 | D44: =IFERROR(INDEX('SubDept Coupon (Local Discount)'!G$1:G$100,MATCH('SubDept Sales Report'!A44,'SubDept Coupon (Local Discount)'!A$1:A$100,0)),0) -> 1.4 | E44: =SUMIF('Maria College 1 Sales Data'!D$11:D$2500,A44,'Maria College 1 Sales Data'!G$11:G$2500) -> 0 | F44: =IFERROR(SUMIF('Maria College 2 Sales Data'!D$11:D$2500,A44,'Maria College 2 Sales Data'!G$11:G$2500),0) -> 0 | G44: =(C44+D44)-E44-F44 -> 15456.28
A45: 420 | B45: Plants & Gardening | C45: =IFERROR(INDEX('SubDept Single'!G$1:G$100,MATCH('SubDept Sales Report'!A45,'SubDept Single'!A$1:A$100,0)),0) -> 2778.06 | D45: =IFERROR(INDEX('SubDept Coupon (Local Discount)'!G$1:G$100,MATCH('SubDept Sales Report'!A45,'SubDept Coupon (Local Discount)'!A$1:A$100,0)),0) -> 8.39 | E45: =SUMIF('Maria College 1 Sales Data'!D$11:D$2500,A45,'Maria College 1 Sales Data'!G$11:G$2500) -> 0 | F45: =IFERROR(SUMIF('Maria College 2 Sales Data'!D$11:D$2500,A45,'Maria College 2 Sales Data'!G$11:G$2500),0) -> 0 | G45: =(C45+D45)-E45-F45 -> 2786.45
A46: 510 | B46: BodyCare (Tax) | C46: =IFERROR(INDEX('SubDept Single'!G$1:G$100,MATCH('SubDept Sales Report'!A46,'SubDept Single'!A$1:A$100,0)),0) -> 2802.17 | D46: =IFERROR(INDEX('SubDept Coupon (Local Discount)'!G$1:G$100,MATCH('SubDept Sales Report'!A46,'SubDept Coupon (Local Discount)'!A$1:A$100,0)),0) -> 0 | E46: =SUMIF('Maria College 1 Sales Data'!D$11:D$2500,A46,'Maria College 1 Sales Data'!G$11:G$2500) -> 0 | F46: =IFERROR(SUMIF('Maria College 2 Sales Data'!D$11:D$2500,A46,'Maria College 2 Sales Data'!G$11:G$2500),0) -> 0 | G46: =(C46+D46)-E46-F46 -> 2802.17
A47: 520 | B47: Supplements | C47: =IFERROR(INDEX('SubDept Single'!G$1:G$100,MATCH('SubDept Sales Report'!A47,'SubDept Single'!A$1:A$100,0)),0) -> 4255.69 | D47: =IFERROR(INDEX('SubDept Coupon (Local Discount)'!G$1:G$100,MATCH('SubDept Sales Report'!A47,'SubDept Coupon (Local Discount)'!A$1:A$100,0)),0) -> 0 | E47: =SUMIF('Maria College 1 Sales Data'!D$11:D$2500,A47,'Maria College 1 Sales Data'!G$11:G$2500) -> 0 | F47: =IFERROR(SUMIF('Maria College 2 Sales Data'!D$11:D$2500,A47,'Maria College 2 Sales Data'!G$11:G$2500),0) -> 0 | G47: =(C47+D47)-E47-F47 -> 4255.69
A48: 530 | B48: Herbs | C48: =IFERROR(INDEX('SubDept Single'!G$1:G$100,MATCH('SubDept Sales Report'!A48,'SubDept Single'!A$1:A$100,0)),0) -> 0 | D48: =IFERROR(INDEX('SubDept Coupon (Local Discount)'!G$1:G$100,MATCH('SubDept Sales Report'!A48,'SubDept Coupon (Local Discount)'!A$1:A$100,0)),0) -> 0 | E48: =SUMIF('Maria College 1 Sales Data'!D$11:D$2500,A48,'Maria College 1 Sales Data'!G$11:G$2500) -> 0 | F48: =IFERROR(SUMIF('Maria College 2 Sales Data'!D$11:D$2500,A48,'Maria College 2 Sales Data'!G$11:G$2500),0) -> 0 | G48: =(C48+D48)-E48-F48 -> 0
A49: 540 | B49: Books | C49: =IFERROR(INDEX('SubDept Single'!G$1:G$100,MATCH('SubDept Sales Report'!A49,'SubDept Single'!A$1:A$100,0)),0) -> 0 | D49: =IFERROR(INDEX('SubDept Coupon (Local Discount)'!G$1:G$100,MATCH('SubDept Sales Report'!A49,'SubDept Coupon (Local Discount)'!A$1:A$100,0)),0) -> 0 | E49: =SUMIF('Maria College 1 Sales Data'!D$11:D$2500,A49,'Maria College 1 Sales Data'!G$11:G$2500) -> 0 | F49: =IFERROR(SUMIF('Maria College 2 Sales Data'!D$11:D$2500,A49,'Maria College 2 Sales Data'!G$11:G$2500),0) -> 0 | G49: =(C49+D49)-E49-F49 -> 0
A50: 550 | B50: Magazines | C50: =IFERROR(INDEX('SubDept Single'!G$1:G$100,MATCH('SubDept Sales Report'!A50,'SubDept Single'!A$1:A$100,0)),0) -> 21.98 | D50: =IFERROR(INDEX('SubDept Coupon (Local Discount)'!G$1:G$100,MATCH('SubDept Sales Report'!A50,'SubDept Coupon (Local Discount)'!A$1:A$100,0)),0) -> 0 | E50: =SUMIF('Maria College 1 Sales Data'!D$11:D$2500,A50,'Maria College 1 Sales Data'!G$11:G$2500) -> 0 | F50: =IFERROR(SUMIF('Maria College 2 Sales Data'!D$11:D$2500,A50,'Maria College 2 Sales Data'!G$11:G$2500),0) -> 0 | G50: =(C50+D50)-E50-F50 -> 21.98
...
